nohup: ignoring input
2025-01-16 11:16:05.465608: I tensorflow/core/platform/cpu_feature_guard.cc:193] This TensorFlow binary is optimized with oneAPI Deep Neural Network Library (oneDNN) to use the following CPU instructions in performance-critical operations:  AVX2 FMA
To enable them in other operations, rebuild TensorFlow with the appropriate compiler flags.
2025-01-16 11:16:05.925063: I tensorflow/core/common_runtime/gpu/gpu_device.cc:1532] Created device /job:localhost/replica:0/task:0/device:GPU:0 with 3083 MB memory:  -> device: 0, name: NVIDIA A100-SXM4-40GB MIG 1g.5gb, pci bus id: 0000:87:00.0, compute capability: 8.0
2025-01-16 11:16:08.849505: I tensorflow/stream_executor/cuda/cuda_dnn.cc:384] Loaded cuDNN version 8100
2025-01-16 11:16:11.613257: I tensorflow/stream_executor/cuda/cuda_blas.cc:1786] TensorFloat-32 will be used for the matrix multiplication. This will only be logged once.
Bot started
1/1 [==============================] - ETA: 0s1/1 [==============================] - 4s 4s/step
1/1 [==============================] - ETA: 0s1/1 [==============================] - 1s 858ms/step
1/1 [==============================] - ETA: 0s1/1 [==============================] - 1s 1s/step
1/1 [==============================] - ETA: 0s1/1 [==============================] - 1s 878ms/step
WARNING:tensorflow:5 out of the last 5 calls to <function Model.make_predict_function.<locals>.predict_function at 0x7fb8efd20280> triggered tf.function retracing. Tracing is expensive and the excessive number of tracings could be due to (1) creating @tf.function repeatedly in a loop, (2) passing tensors with different shapes, (3) passing Python objects instead of tensors. For (1), please define your @tf.function outside of the loop. For (2), @tf.function has reduce_retracing=True option that can avoid unnecessary retracing. For (3), please refer to https://www.tensorflow.org/guide/function#controlling_retracing and https://www.tensorflow.org/api_docs/python/tf/function for  more details.
1/1 [==============================] - ETA: 0s1/1 [==============================] - 1s 877ms/step
WARNING:tensorflow:6 out of the last 6 calls to <function Model.make_predict_function.<locals>.predict_function at 0x7fb8efdeee50> triggered tf.function retracing. Tracing is expensive and the excessive number of tracings could be due to (1) creating @tf.function repeatedly in a loop, (2) passing tensors with different shapes, (3) passing Python objects instead of tensors. For (1), please define your @tf.function outside of the loop. For (2), @tf.function has reduce_retracing=True option that can avoid unnecessary retracing. For (3), please refer to https://www.tensorflow.org/guide/function#controlling_retracing and https://www.tensorflow.org/api_docs/python/tf/function for  more details.
1/1 [==============================] - ETA: 0s1/1 [==============================] - 1s 996ms/step
1/1 [==============================] - ETA: 0s1/1 [==============================] - 1s 1s/step
1/1 [==============================] - ETA: 0s1/1 [==============================] - 1s 883ms/step
An error occurred: HTTPSConnectionPool(host='api.telegram.org', port=443): Read timed out. (read timeout=40)
An error occurred: ('Connection aborted.', ConnectionResetError(104, 'Connection reset by peer'))
An error occurred: HTTPSConnectionPool(host='api.telegram.org', port=443): Read timed out. (read timeout=40)
An error occurred: ('Connection aborted.', ConnectionResetError(104, 'Connection reset by peer'))
An error occurred: ('Connection aborted.', ConnectionResetError(104, 'Connection reset by peer'))
An error occurred: ('Connection aborted.', ConnectionResetError(104, 'Connection reset by peer'))
An error occurred: ('Connection aborted.', ConnectionResetError(104, 'Connection reset by peer'))
An error occurred: ('Connection aborted.', ConnectionResetError(104, 'Connection reset by peer'))
An error occurred: ('Connection aborted.', ConnectionResetError(104, 'Connection reset by peer'))
An error occurred: ('Connection aborted.', ConnectionResetError(104, 'Connection reset by peer'))
An error occurred: ('Connection aborted.', ConnectionResetError(104, 'Connection reset by peer'))
An error occurred: HTTPSConnectionPool(host='api.telegram.org', port=443): Read timed out. (read timeout=40)
An error occurred: ('Connection aborted.', RemoteDisconnected('Remote end closed connection without response'))
An error occurred: HTTPSConnectionPool(host='api.telegram.org', port=443): Read timed out. (read timeout=40)
An error occurred: ('Connection aborted.', ConnectionResetError(104, 'Connection reset by peer'))
An error occurred: HTTPSConnectionPool(host='api.telegram.org', port=443): Read timed out. (read timeout=40)
An error occurred: ('Connection aborted.', ConnectionResetError(104, 'Connection reset by peer'))
An error occurred: ('Connection aborted.', ConnectionResetError(104, 'Connection reset by peer'))
An error occurred: HTTPSConnectionPool(host='api.telegram.org', port=443): Read timed out. (read timeout=40)
An error occurred: ('Connection aborted.', ConnectionResetError(104, 'Connection reset by peer'))
An error occurred: ('Connection aborted.', ConnectionResetError(104, 'Connection reset by peer'))
An error occurred: ('Connection aborted.', ConnectionResetError(104, 'Connection reset by peer'))
An error occurred: ('Connection aborted.', ConnectionResetError(104, 'Connection reset by peer'))
An error occurred: ('Connection aborted.', ConnectionResetError(104, 'Connection reset by peer'))
An error occurred: ('Connection aborted.', ConnectionResetError(104, 'Connection reset by peer'))
An error occurred: HTTPSConnectionPool(host='api.telegram.org', port=443): Read timed out. (read timeout=40)
An error occurred: ('Connection aborted.', ConnectionResetError(104, 'Connection reset by peer'))
An error occurred: ('Connection aborted.', ConnectionResetError(104, 'Connection reset by peer'))
An error occurred: ('Connection aborted.', ConnectionResetError(104, 'Connection reset by peer'))
An error occurred: ('Connection aborted.', ConnectionResetError(104, 'Connection reset by peer'))
An error occurred: HTTPSConnectionPool(host='api.telegram.org', port=443): Read timed out. (read timeout=40)
An error occurred: HTTPSConnectionPool(host='api.telegram.org', port=443): Read timed out. (read timeout=40)
An error occurred: ('Connection aborted.', ConnectionResetError(104, 'Connection reset by peer'))
An error occurred: ('Connection aborted.', ConnectionResetError(104, 'Connection reset by peer'))
An error occurred: ('Connection aborted.', ConnectionResetError(104, 'Connection reset by peer'))
An error occurred: HTTPSConnectionPool(host='api.telegram.org', port=443): Read timed out. (read timeout=40)
An error occurred: ('Connection aborted.', ConnectionResetError(104, 'Connection reset by peer'))
An error occurred: ('Connection aborted.', ConnectionResetError(104, 'Connection reset by peer'))
An error occurred: ('Connection aborted.', ConnectionResetError(104, 'Connection reset by peer'))
An error occurred: ('Connection aborted.', ConnectionResetError(104, 'Connection reset by peer'))
An error occurred: HTTPSConnectionPool(host='api.telegram.org', port=443): Read timed out. (read timeout=40)
An error occurred: HTTPSConnectionPool(host='api.telegram.org', port=443): Read timed out. (read timeout=40)
An error occurred: HTTPSConnectionPool(host='api.telegram.org', port=443): Read timed out. (read timeout=40)
An error occurred: ('Connection aborted.', ConnectionResetError(104, 'Connection reset by peer'))
An error occurred: HTTPSConnectionPool(host='api.telegram.org', port=443): Read timed out. (read timeout=40)
An error occurred: HTTPSConnectionPool(host='api.telegram.org', port=443): Read timed out. (read timeout=40)
An error occurred: ('Connection aborted.', ConnectionResetError(104, 'Connection reset by peer'))
An error occurred: ('Connection aborted.', ConnectionResetError(104, 'Connection reset by peer'))
An error occurred: ('Connection aborted.', ConnectionResetError(104, 'Connection reset by peer'))
An error occurred: ('Connection aborted.', ConnectionResetError(104, 'Connection reset by peer'))
An error occurred: ('Connection aborted.', ConnectionResetError(104, 'Connection reset by peer'))
An error occurred: ('Connection aborted.', RemoteDisconnected('Remote end closed connection without response'))
An error occurred: ('Connection aborted.', ConnectionResetError(104, 'Connection reset by peer'))
An error occurred: ('Connection aborted.', ConnectionResetError(104, 'Connection reset by peer'))
An error occurred: ('Connection aborted.', ConnectionResetError(104, 'Connection reset by peer'))
An error occurred: ('Connection aborted.', ConnectionResetError(104, 'Connection reset by peer'))
An error occurred: HTTPSConnectionPool(host='api.telegram.org', port=443): Max retries exceeded with url: /bot7362412830:AAEmc5Y_Ie0dcfMjSJRMrP9C8_MP4EX6tTk/getUpdates?offset=456563335&timeout=20 (Caused by NewConnectionError('<urllib3.connection.HTTPSConnection object at 0x7fb8efc786a0>: Failed to establish a new connection: [Errno -3] Temporary failure in name resolution'))
An error occurred: ('Connection aborted.', ConnectionResetError(104, 'Connection reset by peer'))
An error occurred: ('Connection aborted.', RemoteDisconnected('Remote end closed connection without response'))
An error occurred: ('Connection aborted.', RemoteDisconnected('Remote end closed connection without response'))
1/1 [==============================] - ETA: 0s1/1 [==============================] - 1s 854ms/step
1/1 [==============================] - ETA: 0s1/1 [==============================] - 1s 1s/step
1/1 [==============================] - ETA: 0s1/1 [==============================] - 1s 895ms/step
1/1 [==============================] - ETA: 0s1/1 [==============================] - 1s 911ms/step
1/1 [==============================] - ETA: 0s1/1 [==============================] - 1s 1s/step
1/1 [==============================] - ETA: 0s1/1 [==============================] - 1s 943ms/step
1/1 [==============================] - ETA: 0s1/1 [==============================] - 1s 873ms/step
1/1 [==============================] - ETA: 0s1/1 [==============================] - 1s 1s/step
2025-01-24 01:10:43,771 (__init__.py:1241 MainThread) ERROR - TeleBot: "Threaded polling exception: A request to the Telegram API was unsuccessful. Error code: 502. Description: Bad Gateway"
2025-01-24 01:10:43,772 (__init__.py:1243 MainThread) ERROR - TeleBot: "Exception traceback:
Traceback (most recent call last):
  File "/opt/conda/lib/python3.8/site-packages/telebot/__init__.py", line 1234, in __threaded_polling
    polling_thread.raise_exceptions()
  File "/opt/conda/lib/python3.8/site-packages/telebot/util.py", line 111, in raise_exceptions
    raise self.exception_info
  File "/opt/conda/lib/python3.8/site-packages/telebot/util.py", line 93, in run
    task(*args, **kwargs)
  File "/opt/conda/lib/python3.8/site-packages/telebot/__init__.py", line 688, in __retrieve_updates
    updates = self.get_updates(offset=(self.last_update_id + 1),
  File "/opt/conda/lib/python3.8/site-packages/telebot/__init__.py", line 660, in get_updates
    json_updates = apihelper.get_updates(
  File "/opt/conda/lib/python3.8/site-packages/telebot/apihelper.py", line 330, in get_updates
    return _make_request(token, method_url, params=payload)
  File "/opt/conda/lib/python3.8/site-packages/telebot/apihelper.py", line 168, in _make_request
    json_result = _check_result(method_name, result)
  File "/opt/conda/lib/python3.8/site-packages/telebot/apihelper.py", line 195, in _check_result
    raise ApiTelegramException(method_name, result, result_json)
telebot.apihelper.ApiTelegramException: A request to the Telegram API was unsuccessful. Error code: 502. Description: Bad Gateway
"
1/1 [==============================] - ETA: 0s1/1 [==============================] - 1s 1s/step
1/1 [==============================] - ETA: 0s1/1 [==============================] - 1s 884ms/step
1/1 [==============================] - ETA: 0s1/1 [==============================] - 1s 869ms/step
1/1 [==============================] - ETA: 0s1/1 [==============================] - 1s 1s/step
1/1 [==============================] - ETA: 0s1/1 [==============================] - 1s 866ms/step
2025-01-31 23:19:36,929 (__init__.py:1241 MainThread) ERROR - TeleBot: "Threaded polling exception: A request to the Telegram API was unsuccessful. Error code: 502. Description: Bad Gateway"
2025-01-31 23:19:36,930 (__init__.py:1243 MainThread) ERROR - TeleBot: "Exception traceback:
Traceback (most recent call last):
  File "/opt/conda/lib/python3.8/site-packages/telebot/__init__.py", line 1234, in __threaded_polling
    polling_thread.raise_exceptions()
  File "/opt/conda/lib/python3.8/site-packages/telebot/util.py", line 111, in raise_exceptions
    raise self.exception_info
  File "/opt/conda/lib/python3.8/site-packages/telebot/util.py", line 93, in run
    task(*args, **kwargs)
  File "/opt/conda/lib/python3.8/site-packages/telebot/__init__.py", line 688, in __retrieve_updates
    updates = self.get_updates(offset=(self.last_update_id + 1),
  File "/opt/conda/lib/python3.8/site-packages/telebot/__init__.py", line 660, in get_updates
    json_updates = apihelper.get_updates(
  File "/opt/conda/lib/python3.8/site-packages/telebot/apihelper.py", line 330, in get_updates
    return _make_request(token, method_url, params=payload)
  File "/opt/conda/lib/python3.8/site-packages/telebot/apihelper.py", line 168, in _make_request
    json_result = _check_result(method_name, result)
  File "/opt/conda/lib/python3.8/site-packages/telebot/apihelper.py", line 195, in _check_result
    raise ApiTelegramException(method_name, result, result_json)
telebot.apihelper.ApiTelegramException: A request to the Telegram API was unsuccessful. Error code: 502. Description: Bad Gateway
"
